<mujoco>
    <worldbody>
        <light diffuse=".5 .5 .5" pos="1 1 10" dir="-0.1 -0.1 -1" />
        <body name="body1" pos="0 0 0.1">
            <joint type="slide" name='slider' axis="1 0 0"/> 
            <geom type="box" name='box' size="0.1 0.1 0.1" rgba="1 0 0 1" group="0"/>
        </body>

        <body name="body3" pos="0.5 0 0.15">
            <joint type="slide" name='slider2' axis="1 0 0"/> 
            <geom type="box" name='box2' size="0.15 0.15 0.15" rgba="0 1 0 1" group="1"/>
        </body>

        <body name="body2" pos="0 0 -0.02">
            <geom name='ground' type="box" size="1 1 0.02 " pos="0 0 0" euler="0 0 0" rgba="0 0 1 1" group="2"/>
        </body>
    </worldbody>
</mujoco>